2022-06-23 08:06:38 ERROR Traceback (most recent call last):
  File "D:\Programming\Python\.aivenv\lib\site-packages\wandb\cli\cli.py", line 96, in wrapper
    return func(*args, **kwargs)
  File "D:\Programming\Python\.aivenv\lib\site-packages\wandb\cli\cli.py", line 244, in login
    wandb.login(relogin=relogin, key=key, anonymous=anon_mode, host=host, force=True)
  File "D:\Programming\Python\.aivenv\lib\site-packages\wandb\sdk\wandb_login.py", line 76, in login
    configured = _login(**kwargs)
  File "D:\Programming\Python\.aivenv\lib\site-packages\wandb\sdk\wandb_login.py", line 297, in _login
    wlogin.prompt_api_key()
  File "D:\Programming\Python\.aivenv\lib\site-packages\wandb\sdk\wandb_login.py", line 227, in prompt_api_key
    raise UsageError("api_key not configured (no-tty). call " + directive)
wandb.errors.UsageError: api_key not configured (no-tty). call wandb login [your_api_key]

